<?xml version="1.0"?>
<robot xmlns:xacro="http://ros.org/wiki/xacro">
  <xacro:macro name="abb_irb6700_245_300" params="prefix">
    <xacro:include filename="$(find abb_irb6700_support)/urdf/common_materials.xacro"/>
    <!-- link list -->
    <link name="${prefix}base_link">
      <visual>
        <origin xyz="0 0 0" rpy="0 0 0" />
        <geometry>
          <mesh filename="package://abb_irb6700_support/meshes/irb6700_245_300/visual/base_link.stl" />
        </geometry>
        <xacro:material_abb_white/>
      </visual>
      <collision>
        <origin xyz="0 0 0" rpy="0 0 0" />
        <geometry>
          <mesh filename="package://abb_irb6700_support/meshes/irb6700_245_300/collision/base_link.stl" />
        </geometry>
        <xacro:material_abb_yellow/>
      </collision>
    </link>
    <link name="${prefix}link_1">
      <visual>
        <origin xyz="0 0 -0.78" rpy="0 0 0" />
        <geometry>
          <mesh filename="package://abb_irb6700_support/meshes/irb6700_245_300/visual/link_1.stl" />
        </geometry>
        <xacro:material_abb_white/>
      </visual>
      <collision>
        <origin xyz="0 0 -0.78" rpy="0 0 0" />
        <geometry>
          <mesh filename="package://abb_irb6700_support/meshes/irb6700_245_300/collision/link_1.stl" />
        </geometry>
        <xacro:material_abb_yellow/>
      </collision>
    </link>
    <link name="${prefix}link_2">
      <visual>
        <origin xyz="-0.35 0 -0.78" rpy="0 0 0" />
        <geometry>
          <mesh filename="package://abb_irb6700_support/meshes/irb6700_245_300/visual/link_2.stl" />
        </geometry>
        <xacro:material_abb_white/>
      </visual>
      <collision>
        <origin xyz="-0.35 0 -0.78" rpy="0 0 0" />
        <geometry>
          <mesh filename="package://abb_irb6700_support/meshes/irb6700_245_300/collision/link_2.stl" />
        </geometry>
        <xacro:material_abb_yellow/>
      </collision>
    </link>
    <link name="${prefix}link_3">
      <visual>
        <origin xyz="-0.35 0 -1.925" rpy="0 0 0" />
        <geometry>
          <mesh filename="package://abb_irb6700_support/meshes/irb6700_245_300/visual/link_3.stl" />
        </geometry>
        <xacro:material_abb_white/>
      </visual>
      <collision>
        <origin xyz="-0.35 0 -1.925" rpy="0 0 0" />
        <geometry>
          <mesh filename="package://abb_irb6700_support/meshes/irb6700_245_300/collision/link_3.stl" />
        </geometry>
        <xacro:material_abb_yellow/>
      </collision>
    </link>
    <link name="${prefix}link_4">
      <visual>
        <origin xyz="-0.35 0 -2.125" rpy="0 0 0" />
        <geometry>
          <mesh filename="package://abb_irb6700_support/meshes/irb6700_245_300/visual/link_4.stl" />
        </geometry>
        <xacro:material_abb_white/>
      </visual>
      <collision>
        <origin xyz="-0.35 0 -2.125" rpy="0 0 0" />
        <geometry>
          <mesh filename="package://abb_irb6700_support/meshes/irb6700_245_300/collision/link_4.stl" />
        </geometry>
        <xacro:material_abb_yellow/>
      </collision>
    </link>
    <link name="${prefix}link_5">
      <visual>
        <origin xyz="-1.8125 0 -2.125" rpy="0 0 0" />
        <geometry>
          <mesh filename="package://abb_irb6700_support/meshes/irb6700_245_300/visual/link_5.stl" />
        </geometry>
        <xacro:material_abb_white/>
      </visual>
      <collision>
        <origin xyz="-1.8125 0 -2.125" rpy="0 0 0" />
        <geometry>
          <mesh filename="package://abb_irb6700_support/meshes/irb6700_245_300/collision/link_5.stl" />
        </geometry>
        <xacro:material_abb_yellow/>
      </collision>
    </link>
    <link name="${prefix}link_6">
      <visual>
        <origin xyz="-2.125 0 -2.0325" rpy="${radians(180)} ${radians(-90)} 0" />
        <geometry>
          <mesh filename="package://abb_irb6700_support/meshes/irb6700_245_300/visual/link_6.stl" />
        </geometry>
        <xacro:material_abb_white/>
      </visual>
      <collision>
        <origin xyz="-2.125 0 -2.0325" rpy="${radians(180)} ${radians(-90)} 0" />
        <geometry>
          <mesh filename="package://abb_irb6700_support/meshes/irb6700_245_300/collision/link_6.stl" />
        </geometry>
        <xacro:material_abb_yellow/>
      </collision>
    </link>

    <joint name="${prefix}joint1" type="revolute">
      <origin xyz="0 0 0.78" rpy="0 0 0" />
      <parent link="${prefix}base_link" />
      <child link="${prefix}link_1" />
      <axis xyz="0 0 1" />
      <limit lower="-${radians(170)}" upper="${radians(170)}" effort="0" velocity="${radians(100)}" />
    </joint>
    <joint name="${prefix}joint2" type="revolute">
      <origin xyz="0.35 0 0" rpy="0 0 0" />
      <parent link="${prefix}link_1" />
      <child link="${prefix}link_2" />
      <axis xyz="0 1 0" />
      <limit lower="-${radians(65)}" upper="${radians(85)}" effort="0" velocity="${radians(88)}" />
    </joint>
    <joint name="${prefix}joint3" type="revolute">
      <origin xyz="0 0 1.145" rpy="0 0 0" />
      <parent link="${prefix}link_2" />
      <child link="${prefix}link_3" />
      <axis xyz="0 1 0" />
      <limit lower="-${radians(180)}" upper="${radians(69)}" effort="0" velocity="${radians(90)}" />
    </joint>
    <joint name="${prefix}joint4" type="revolute">
      <origin xyz="0 0 0.2" rpy="0 0 0" />
      <parent link="${prefix}link_3" />
      <child link="${prefix}link_4" />
      <axis xyz="1 0 0" />
      <limit lower="-${radians(300)}" upper="${radians(300)}" effort="0" velocity="${radians(140)}" />
    </joint>
    <joint name="${prefix}joint5" type="revolute">
      <origin xyz="1.4625 0 0" rpy="0 0 0" />
      <parent link="${prefix}link_4" />
      <child link="${prefix}link_5" />
      <axis xyz="0 1 0" />
      <limit lower="-${radians(130)}" upper="${radians(130)}" effort="0" velocity="${radians(110)}" />
    </joint>
    <joint name="${prefix}joint6" type="revolute">
      <origin xyz="0.22 0 0" rpy="0 ${radians(90)} 0" />
      <parent link="${prefix}link_5" />
      <child link="${prefix}link_6" />
      <axis xyz="0 0 1" />
      <limit lower="-${radians(360)}" upper="${radians(360)}" effort="0" velocity="${radians(180)}" />
    </joint>
    
  </xacro:macro>

  <transform>
    <xacro:attribute name="tf_rb_ub" value="0.0 0.0 0.0 0.0 0.0 0.0 1.0"/>
    <xacro:attribute name="tf_rf_uf" value="0.0 0.0 0.0 0.0 0.0 0.0 1.0"/>
  </transform>
  <constraint coeff="0.0 0.0 0.0 1.0 0.0 0.0" upper_bound="0.0" lower_bound="0.0"/>
  <constraint coeff="0.0 1.0 1.0 0.0 1.0 0.0" upper_bound="${radians(90)}" lower_bound="${radians(90)}"/>
  
</robot>
