<?xml version="1.0" ?>
<!-- =================================================================================== -->
<!-- |    This document was autogenerated by xacro from kr180_r2900_2.xacro            | -->
<!-- |    EDITING THIS FILE BY HAND IS NOT RECOMMENDED                                 | -->
<!-- =================================================================================== -->
<robot name="kuka_kr180_r2900_2">
  <!-- colours based on RAL values given in "FAQ - Colours of robot and robot
       controller", version "KUKA.Tifs | 2010-01-21 |YM| DefaultColorsRobotAndController.doc",
       downloaded 2015-07-18 from
       http://www.kuka.be/main/cservice/faqs/hardware/DefaultColorsRobotAndController.pdf

       all RAL colours converted using http://www.visual-graphics.de/en/customer-care/ral-colours
  -->
  <!-- colours based on RAL values given in "FAQ - Colours of robot and robot
       controller", version "KUKA.Tifs | 2010-01-21 |YM| DefaultColorsRobotAndController.doc",
       downloaded 2015-07-18 from
       http://www.kuka.be/main/cservice/faqs/hardware/DefaultColorsRobotAndController.pdf

       all RAL colours converted using http://www.visual-graphics.de/en/customer-care/ral-colours
  -->
  <transform tf_rb_ub="0.0 0.0 0.0 0.0 0.0 0.0 1.0" tf_rf_uf="0.0 0.0 0.0 0.0 0.0 0.0 1.0">
  </transform>
  <constraint coeff="0.0 0.0 0.0 1.0 0.0 0.0" lower_bound="0.0" upper_bound="0.0"/>
  <constraint coeff="0.0 1.0 1.0 0.0 1.0 0.0" lower_bound="1.5707963267948966" upper_bound="1.5707963267948966"/>
  <link name="base_link">
    <visual>
      <origin rpy="0 0 0" xyz="0 0 0"/>
      <geometry>
        <mesh filename="package://kuka_kr180_support/meshes/kr180_r2900_2/visual/base_link.stl"/>
      </geometry>
      <material name="">
        <color rgba="0.054901960784313725 0.054901960784313725 0.06274509803921569 1.0"/>
      </material>
    </visual>
    <collision>
      <origin rpy="0 0 0" xyz="0 0 0"/>
      <geometry>
        <mesh filename="package://kuka_kr180_support/meshes/kr180_r2900_2/collision/base_link.stl"/>
      </geometry>
    </collision>
  </link>
  <link name="link_1">
    <visual>
      <origin rpy="0 0 0" xyz="0 0 -0.645"/>
      <geometry>
        <mesh filename="package://kuka_kr180_support/meshes/kr180_r2900_2/visual/link_1.stl"/>
      </geometry>
      <material name="">
        <color rgba="0.9647058823529412 0.47058823529411764 0.1568627450980392 1.0"/>
      </material>
    </visual>
    <collision>
      <origin rpy="0 0 0" xyz="0 0 -0.645"/>
      <geometry>
        <mesh filename="package://kuka_kr180_support/meshes/kr180_r2900_2/collision/link_1.stl"/>
      </geometry>
    </collision>
  </link>
  <link name="link_2">
    <visual>
      <origin rpy="0 0 0" xyz="-0.33 0 -0.645"/>
      <geometry>
        <mesh filename="package://kuka_kr180_support/meshes/kr180_r2900_2/visual/link_2.stl"/>
      </geometry>
      <material name="">
        <color rgba="0.9647058823529412 0.47058823529411764 0.1568627450980392 1.0"/>
      </material>
    </visual>
    <collision>
      <origin rpy="0 0 0" xyz="-0.33 0 -0.645"/>
      <geometry>
        <mesh filename="package://kuka_kr180_support/meshes/kr180_r2900_2/collision/link_2.stl"/>
      </geometry>
    </collision>
  </link>
  <link name="link_3">
    <visual>
      <origin rpy="0 0 0" xyz="-0.33 0 -1.995"/>
      <geometry>
        <mesh filename="package://kuka_kr180_support/meshes/kr180_r2900_2/visual/link_3.stl"/>
      </geometry>
      <material name="">
        <color rgba="0.9647058823529412 0.47058823529411764 0.1568627450980392 1.0"/>
      </material>
    </visual>
    <collision>
      <origin rpy="0 0 0" xyz="-0.33 0 -1.995"/>
      <geometry>
        <mesh filename="package://kuka_kr180_support/meshes/kr180_r2900_2/collision/link_3.stl"/>
      </geometry>
    </collision>
  </link>
  <link name="link_4">
    <visual>
      <origin rpy="0 0 0" xyz="-0.33 0 -2.11"/>
      <geometry>
        <mesh filename="package://kuka_kr180_support/meshes/kr180_r2900_2/visual/link_4.stl"/>
      </geometry>
      <material name="">
        <color rgba="0.9647058823529412 0.47058823529411764 0.1568627450980392 1.0"/>
      </material>
    </visual>
    <collision>
      <origin rpy="0 0 0" xyz="-0.33 0 -2.11"/>
      <geometry>
        <mesh filename="package://kuka_kr180_support/meshes/kr180_r2900_2/collision/link_4.stl"/>
      </geometry>
    </collision>
  </link>
  <link name="link_5">
    <visual>
      <origin rpy="0 0 0" xyz="-1.55 0 -2.11"/>
      <geometry>
        <mesh filename="package://kuka_kr180_support/meshes/kr180_r2900_2/visual/link_5.stl"/>
      </geometry>
      <material name="">
        <color rgba="0.9647058823529412 0.47058823529411764 0.1568627450980392 1.0"/>
      </material>
    </visual>
    <collision>
      <origin rpy="0 0 0" xyz="-1.55 0 -2.11"/>
      <geometry>
        <mesh filename="package://kuka_kr180_support/meshes/kr180_r2900_2/collision/link_5.stl"/>
      </geometry>
    </collision>
  </link>
  <link name="link_6">
    <visual>
      <origin rpy="0 -1.5707963267948966 0" xyz="2.11 0 -1.79"/>
      <geometry>
        <mesh filename="package://kuka_kr180_support/meshes/kr180_r2900_2/visual/link_6.stl"/>
      </geometry>
      <material name="">
        <color rgba="0.054901960784313725 0.054901960784313725 0.06274509803921569 1.0"/>
      </material>
    </visual>
    <collision>
      <origin rpy="0 -1.5707963267948966 0" xyz="2.11 0 -1.79"/>
      <geometry>
        <mesh filename="package://kuka_kr180_support/meshes/kr180_r2900_2/collision/link_6.stl"/>
      </geometry>
    </collision>
  </link>
  <joint name="joint1" type="revolute">
    <origin rpy="0 0 0" xyz="0 0 0.645"/>
    <parent link="base_link"/>
    <child link="link_1"/>
    <axis xyz="0 0 -1"/>
    <limit effort="0" lower="-3.2288591161895095" upper="3.2288591161895095" velocity="1.8325957145940461"/>
  </joint>
  <joint name="joint2" type="revolute">
    <origin rpy="0 1.5707963267948966 0" xyz="0.330 0 0.0"/>
    <parent link="link_1"/>
    <child link="link_2"/>
    <axis xyz="0 1 0"/>
    <limit effort="0" lower="-2.443460952792061" upper="-0.08726646259971647" velocity="1.8675022996339325"/>
  </joint>
  <joint name="joint3" type="revolute">
    <origin rpy="0 -1.5707963267948966 0" xyz="0 0 1.350"/>
    <parent link="link_2"/>
    <child link="link_3"/>
    <axis xyz="0 1 0"/>
    <limit effort="0" lower="-2.0943951023931953" upper="2.9321531433504737" velocity="1.9896753472735358"/>
  </joint>
  <joint name="joint4" type="revolute">
    <origin rpy="0 0 0" xyz="0 0 0.115"/>
    <parent link="link_3"/>
    <child link="link_4"/>
    <axis xyz="-1 0 0"/>
    <limit effort="0" lower="-6.1086523819801535" upper="6.1086523819801535" velocity="3.12413936106985"/>
  </joint>
  <joint name="joint5" type="revolute">
    <origin rpy="0 0 0" xyz="1.22 0 0"/>
    <parent link="link_4"/>
    <child link="link_5"/>
    <axis xyz="0 1 0"/>
    <limit effort="0" lower="-2.138028333693054" upper="2.138028333693054" velocity="3.001966313430247"/>
  </joint>
  <joint name="joint6" type="revolute">
    <origin rpy="0 1.5707963267948966 0" xyz="0.240 0 0"/>
    <parent link="link_5"/>
    <child link="link_6"/>
    <axis xyz="0 0 -1"/>
    <limit effort="0" lower="-6.1086523819801535" upper="6.1086523819801535" velocity="3.822271061867582"/>
  </joint>
</robot>
