<?xml version="1.0" ?>
<!-- =================================================================================== -->
<!-- |    This document was autogenerated by xacro from irb6700_245_300.xacro          | -->
<!-- |    EDITING THIS FILE BY HAND IS NOT RECOMMENDED                                 | -->
<!-- =================================================================================== -->
<robot name="abb_irb6700_245_300">
  <transform tf_rb_ub="0.0 0.0 0.0 0.0 0.0 0.0 1.0" tf_rf_uf="0.0 0.0 0.0 0.0 0.0 0.0 1.0">
  </transform>
  <constraint coeff="0.0 0.0 0.0 1.0 0.0 0.0" lower_bound="0.0" upper_bound="0.0"/>
  <constraint coeff="0.0 1.0 1.0 0.0 1.0 0.0" lower_bound="1.5707963267948966" upper_bound="1.5707963267948966"/>
  <!-- Conversion were obtained from http://www.e-paint.co.uk/Lab_values.asp
       unless otherwise stated. -->
  <!-- link list -->
  <link name="base_link">
    <visual>
      <origin rpy="0 0 0" xyz="0 0 0"/>
      <geometry>
        <mesh filename="package://abb_irb6700_support/meshes/irb6700_245_300/visual/base_link.stl"/>
      </geometry>
      <material name="">
        <color rgba="0.9254902 0.9254902 0.9058824 1"/>
      </material>
    </visual>
    <collision>
      <origin rpy="0 0 0" xyz="0 0 0"/>
      <geometry>
        <mesh filename="package://abb_irb6700_support/meshes/irb6700_245_300/collision/base_link.stl"/>
      </geometry>
      <material name="">
        <color rgba="1 1 0 1"/>
      </material>
    </collision>
  </link>
  <link name="link_1">
    <visual>
      <origin rpy="0 0 0" xyz="0 0 -0.78"/>
      <geometry>
        <mesh filename="package://abb_irb6700_support/meshes/irb6700_245_300/visual/link_1.stl"/>
      </geometry>
      <material name="">
        <color rgba="0.9254902 0.9254902 0.9058824 1"/>
      </material>
    </visual>
    <collision>
      <origin rpy="0 0 0" xyz="0 0 -0.78"/>
      <geometry>
        <mesh filename="package://abb_irb6700_support/meshes/irb6700_245_300/collision/link_1.stl"/>
      </geometry>
      <material name="">
        <color rgba="1 1 0 1"/>
      </material>
    </collision>
  </link>
  <link name="link_2">
    <visual>
      <origin rpy="0 0 0" xyz="-0.35 0 -0.78"/>
      <geometry>
        <mesh filename="package://abb_irb6700_support/meshes/irb6700_245_300/visual/link_2.stl"/>
      </geometry>
      <material name="">
        <color rgba="0.9254902 0.9254902 0.9058824 1"/>
      </material>
    </visual>
    <collision>
      <origin rpy="0 0 0" xyz="-0.35 0 -0.78"/>
      <geometry>
        <mesh filename="package://abb_irb6700_support/meshes/irb6700_245_300/collision/link_2.stl"/>
      </geometry>
      <material name="">
        <color rgba="1 1 0 1"/>
      </material>
    </collision>
  </link>
  <link name="link_3">
    <visual>
      <origin rpy="0 0 0" xyz="-0.35 0 -1.925"/>
      <geometry>
        <mesh filename="package://abb_irb6700_support/meshes/irb6700_245_300/visual/link_3.stl"/>
      </geometry>
      <material name="">
        <color rgba="0.9254902 0.9254902 0.9058824 1"/>
      </material>
    </visual>
    <collision>
      <origin rpy="0 0 0" xyz="-0.35 0 -1.925"/>
      <geometry>
        <mesh filename="package://abb_irb6700_support/meshes/irb6700_245_300/collision/link_3.stl"/>
      </geometry>
      <material name="">
        <color rgba="1 1 0 1"/>
      </material>
    </collision>
  </link>
  <link name="link_4">
    <visual>
      <origin rpy="0 0 0" xyz="-0.35 0 -2.125"/>
      <geometry>
        <mesh filename="package://abb_irb6700_support/meshes/irb6700_245_300/visual/link_4.stl"/>
      </geometry>
      <material name="">
        <color rgba="0.9254902 0.9254902 0.9058824 1"/>
      </material>
    </visual>
    <collision>
      <origin rpy="0 0 0" xyz="-0.35 0 -2.125"/>
      <geometry>
        <mesh filename="package://abb_irb6700_support/meshes/irb6700_245_300/collision/link_4.stl"/>
      </geometry>
      <material name="">
        <color rgba="1 1 0 1"/>
      </material>
    </collision>
  </link>
  <link name="link_5">
    <visual>
      <origin rpy="0 0 0" xyz="-1.8125 0 -2.125"/>
      <geometry>
        <mesh filename="package://abb_irb6700_support/meshes/irb6700_245_300/visual/link_5.stl"/>
      </geometry>
      <material name="">
        <color rgba="0.9254902 0.9254902 0.9058824 1"/>
      </material>
    </visual>
    <collision>
      <origin rpy="0 0 0" xyz="-1.8125 0 -2.125"/>
      <geometry>
        <mesh filename="package://abb_irb6700_support/meshes/irb6700_245_300/collision/link_5.stl"/>
      </geometry>
      <material name="">
        <color rgba="1 1 0 1"/>
      </material>
    </collision>
  </link>
  <link name="link_6">
    <visual>
      <origin rpy="3.141592653589793 -1.5707963267948966 0" xyz="-2.125 0 -2.0325"/>
      <geometry>
        <mesh filename="package://abb_irb6700_support/meshes/irb6700_245_300/visual/link_6.stl"/>
      </geometry>
      <material name="">
        <color rgba="0.9254902 0.9254902 0.9058824 1"/>
      </material>
    </visual>
    <collision>
      <origin rpy="3.141592653589793 -1.5707963267948966 0" xyz="-2.125 0 -2.0325"/>
      <geometry>
        <mesh filename="package://abb_irb6700_support/meshes/irb6700_245_300/collision/link_6.stl"/>
      </geometry>
      <material name="">
        <color rgba="1 1 0 1"/>
      </material>
    </collision>
  </link>
  <joint name="joint1" type="revolute">
    <origin rpy="0 0 0" xyz="0 0 0.78"/>
    <parent link="base_link"/>
    <child link="link_1"/>
    <axis xyz="0 0 1"/>
    <limit effort="0" lower="-2.9670597283903604" upper="2.9670597283903604" velocity="1.7453292519943295"/>
  </joint>
  <joint name="joint2" type="revolute">
    <origin rpy="0 0 0" xyz="0.35 0 0"/>
    <parent link="link_1"/>
    <child link="link_2"/>
    <axis xyz="0 1 0"/>
    <limit effort="0" lower="-1.1344640137963142" upper="1.4835298641951802" velocity="1.53588974175501"/>
  </joint>
  <joint name="joint3" type="revolute">
    <origin rpy="0 0 0" xyz="0 0 1.145"/>
    <parent link="link_2"/>
    <child link="link_3"/>
    <axis xyz="0 1 0"/>
    <limit effort="0" lower="-3.141592653589793" upper="1.2042771838760873" velocity="1.5707963267948966"/>
  </joint>
  <joint name="joint4" type="revolute">
    <origin rpy="0 0 0" xyz="0 0 0.2"/>
    <parent link="link_3"/>
    <child link="link_4"/>
    <axis xyz="1 0 0"/>
    <limit effort="0" lower="-5.235987755982989" upper="5.235987755982989" velocity="2.443460952792061"/>
  </joint>
  <joint name="joint5" type="revolute">
    <origin rpy="0 0 0" xyz="1.4625 0 0"/>
    <parent link="link_4"/>
    <child link="link_5"/>
    <axis xyz="0 1 0"/>
    <limit effort="0" lower="-2.2689280275926285" upper="2.2689280275926285" velocity="1.9198621771937625"/>
  </joint>
  <joint name="joint6" type="revolute">
    <origin rpy="0 1.5707963267948966 0" xyz="0.22 0 0"/>
    <parent link="link_5"/>
    <child link="link_6"/>
    <axis xyz="0 0 1"/>
    <limit effort="0" lower="-6.283185307179586" upper="6.283185307179586" velocity="3.141592653589793"/>
  </joint>
</robot>
