<?xml version="1.0"?>
<robot xmlns:xacro="http://wiki.ros.org/xacro">
  <xacro:include filename="$(find kuka_kr180_support)/urdf/common_constants.xacro"/>
  <xacro:include filename="$(find kuka_kr180_support)/urdf/common_materials.xacro"/>
  <xacro:include filename="$(find kuka_kr180_support)/urdf/common_colours.xacro"/>

  <xacro:macro name="kuka_kr180_r2900_2" params="prefix">
    <link name="${prefix}base_link">
      <visual>
        <origin xyz="0 0 0" rpy="0 0 0"/>
        <geometry>
          <mesh filename="package://kuka_kr180_support/meshes/kr180_r2900_2/visual/base_link.stl" />
        </geometry>
        <xacro:material_kuka_black />
      </visual>
      <collision>
        <origin xyz="0 0 0" rpy="0 0 0"/>
        <geometry>
          <mesh filename="package://kuka_kr180_support/meshes/kr180_r2900_2/collision/base_link.stl" />
        </geometry>
      </collision>
    </link>
    <link name="${prefix}link_1">
      <visual>
        <origin xyz="0 0 -0.645" rpy="0 0 0"/>
        <geometry>
          <mesh filename="package://kuka_kr180_support/meshes/kr180_r2900_2/visual/link_1.stl" />
        </geometry>
        <xacro:material_kuka_orange />
      </visual>
      <collision>
        <origin xyz="0 0 -0.645" rpy="0 0 0"/>
        <geometry>
          <mesh filename="package://kuka_kr180_support/meshes/kr180_r2900_2/collision/link_1.stl" />
        </geometry>
      </collision>
    </link>
    <link name="${prefix}link_2">
      <visual>
        <origin xyz="-0.33 0 -0.645" rpy="0 0 0"/>
        <geometry>
          <mesh filename="package://kuka_kr180_support/meshes/kr180_r2900_2/visual/link_2.stl"/>
        </geometry>
        <xacro:material_kuka_orange />
      </visual>
      <collision>
        <origin xyz="-0.33 0 -0.645" rpy="0 0 0"/>
        <geometry>
          <mesh filename="package://kuka_kr180_support/meshes/kr180_r2900_2/collision/link_2.stl" />
        </geometry>
      </collision>
    </link>
    <link name="${prefix}link_3">
      <visual>
        <origin xyz="-0.33 0 -1.995" rpy="0 0 0"/>
        <geometry>
          <mesh filename="package://kuka_kr180_support/meshes/kr180_r2900_2/visual/link_3.stl" />
        </geometry>
        <xacro:material_kuka_orange />
      </visual>
      <collision>
        <origin xyz="-0.33 0 -1.995" rpy="0 0 0"/>
        <geometry>
          <mesh filename="package://kuka_kr180_support/meshes/kr180_r2900_2/collision/link_3.stl" />
        </geometry>
      </collision>
    </link>
    <link name="${prefix}link_4">
      <visual>
        <origin xyz="-0.33 0 -2.11" rpy="0 0 0"/>
        <geometry>
          <mesh filename="package://kuka_kr180_support/meshes/kr180_r2900_2/visual/link_4.stl" />
        </geometry>
        <xacro:material_kuka_orange />
      </visual>
      <collision>
        <origin xyz="-0.33 0 -2.11" rpy="0 0 0"/>
        <geometry>
          <mesh filename="package://kuka_kr180_support/meshes/kr180_r2900_2/collision/link_4.stl" />
        </geometry>
      </collision>
    </link>
    <link name="${prefix}link_5">
      <visual>
        <origin xyz="-1.55 0 -2.11" rpy="0 0 0"/>
        <geometry>
          <mesh filename="package://kuka_kr180_support/meshes/kr180_r2900_2/visual/link_5.stl" />
        </geometry>
        <xacro:material_kuka_orange />
      </visual>
      <collision>
        <origin xyz="-1.55 0 -2.11" rpy="0 0 0"/>
        <geometry>
          <mesh filename="package://kuka_kr180_support/meshes/kr180_r2900_2/collision/link_5.stl" />
        </geometry>
      </collision>
    </link>
    <link name="${prefix}link_6">
      <visual>
        <origin xyz="2.11 0 -1.79" rpy="0 ${-90 * DEG2RAD} 0"/>
        <geometry>
          <mesh filename="package://kuka_kr180_support/meshes/kr180_r2900_2/visual/link_6.stl" />
        </geometry>
        <xacro:material_kuka_black />
      </visual>
      <collision>
        <origin xyz="2.11 0 -1.79" rpy="0 ${-90 * DEG2RAD} 0"/>
        <geometry>
          <mesh filename="package://kuka_kr180_support/meshes/kr180_r2900_2/collision/link_6.stl" />
        </geometry>
      </collision>
    </link>

    <joint name="${prefix}joint1" type="revolute">
      <origin xyz="0 0 0.645" rpy="0 0 0"/>
      <parent link="${prefix}base_link"/>
      <child link="${prefix}link_1"/>
      <axis xyz="0 0 -1"/>
      <limit effort="0" lower="${-185 * DEG2RAD}" upper="${185 * DEG2RAD}" velocity="${105 * DEG2RAD}"/>
    </joint>
    <joint name="${prefix}joint2" type="revolute">
      <origin xyz="0.330 0 0.0" rpy="0 ${90 * DEG2RAD} 0"/>
      <parent link="${prefix}link_1"/>
      <child link="${prefix}link_2"/>
      <axis xyz="0 1 0"/>
      <limit effort="0" lower="${-140 * DEG2RAD}" upper="${-5 * DEG2RAD}" velocity="${107 * DEG2RAD}"/>
    </joint>
    <joint name="${prefix}joint3" type="revolute">
      <origin xyz="0 0 1.350" rpy="0 ${-90 * DEG2RAD} 0"/>
      <parent link="${prefix}link_2"/>
      <child link="${prefix}link_3"/>
      <axis xyz="0 1 0"/>
      <limit effort="0" lower="${-120 * DEG2RAD}" upper="${168 * DEG2RAD}" velocity="${114 * DEG2RAD}"/>
    </joint>
    <joint name="${prefix}joint4" type="revolute">
      <origin xyz="0 0 0.115" rpy="0 0 0"/>
      <parent link="${prefix}link_3"/>
      <child link="${prefix}link_4"/>
      <axis xyz="-1 0 0"/>
      <limit effort="0" lower="${-350 * DEG2RAD}" upper="${350 * DEG2RAD}" velocity="${179 * DEG2RAD}"/>
    </joint>
    <joint name="${prefix}joint5" type="revolute">
      <origin xyz="1.22 0 0" rpy="0 0 0"/>
      <parent link="${prefix}link_4"/>
      <child link="${prefix}link_5"/>
      <axis xyz="0 1 0"/>
      <limit effort="0" lower="${-122.5 * DEG2RAD}" upper="${122.5 * DEG2RAD}" velocity="${172 * DEG2RAD}"/>
    </joint>
    <joint name="${prefix}joint6" type="revolute">
      <origin xyz="0.240 0 0" rpy="0 ${90 * DEG2RAD} 0"/>
      <parent link="${prefix}link_5"/>
      <child link="${prefix}link_6"/>
      <axis xyz="0 0 -1"/>
      <limit effort="0" lower="${-350 * DEG2RAD}" upper="${350 * DEG2RAD}" velocity="${219 * DEG2RAD}"/>
    </joint>
  </xacro:macro>

  <transform>
    <xacro:attribute name="tf_rb_ub" value="0.0 0.0 0.0 0.0 0.0 0.0 1.0"/>
    <xacro:attribute name="tf_rf_uf" value="0.0 0.0 0.0 0.0 0.0 0.0 1.0"/>
  </transform>
  <constraint coeff="0.0 0.0 0.0 1.0 0.0 0.0" upper_bound="0.0" lower_bound="0.0"/>
  <constraint coeff="0.0 1.0 1.0 0.0 1.0 0.0" upper_bound="1.5707963267948966" lower_bound="1.5707963267948966"/>

</robot>
