<?xml version="1.0"?>
<robot xmlns:xacro="http://wiki.ros.org/xacro">
  <xacro:include filename="$(find kuka_kr180_support)/urdf/common_constants.xacro"/>
  <xacro:include filename="$(find kuka_kr180_support)/urdf/common_materials.xacro"/>
  <xacro:include filename="$(find kuka_kr180_support)/urdf/common_colours.xacro"/>

  <xacro:macro name="kuka_kr180_r3200_pa" params="prefix">
    <link name="${prefix}base_link">
      <visual>
        <origin xyz="0 0 0" rpy="0 0 0"/>
        <geometry>
          <mesh filename="package://kuka_kr180_support/meshes/kr180_r3200_pa/visual/base_link.stl" />
        </geometry>
        <xacro:material_kuka_black />
      </visual>
      <collision>
        <origin xyz="0 0 0" rpy="0 0 0"/>
        <geometry>
          <mesh filename="package://kuka_kr180_support/meshes/kr180_r3200_pa/collision/base_link.stl" />
        </geometry>
      </collision>
    </link>
    <link name="${prefix}link_1">
      <visual>
        <origin xyz="0 0 -0.675" rpy="0 0 0"/>
        <geometry>
          <mesh filename="package://kuka_kr180_support/meshes/kr180_r3200_pa/visual/link_1.stl" />
        </geometry>
        <xacro:material_kuka_orange />
      </visual>
      <collision>
        <origin xyz="0 0 -0.675" rpy="0 0 0"/>
        <geometry>
          <mesh filename="package://kuka_kr180_support/meshes/kr180_r3200_pa/collision/link_1.stl" />
        </geometry>
      </collision>
    </link>
    <link name="${prefix}link_2">
      <visual>
        <origin xyz="-0.35 0 -0.675" rpy="0 0 0"/>
        <geometry>
          <mesh filename="package://kuka_kr180_support/meshes/kr180_r3200_pa/visual/link_2.stl"/>
        </geometry>
        <xacro:material_kuka_orange />
      </visual>
      <collision>
        <origin xyz="-0.35 0 -0.675" rpy="0 0 0"/>
        <geometry>
          <mesh filename="package://kuka_kr180_support/meshes/kr180_r3200_pa/collision/link_2.stl" />
        </geometry>
      </collision>
    </link>
    <link name="${prefix}link_3">
      <visual>
        <origin xyz="0 0 0" rpy="0 0 0"/>
        <geometry>
          <mesh filename="package://kuka_kr180_support/meshes/kr180_r3200_pa/visual/link_3.stl" />
        </geometry>
        <xacro:material_kuka_orange />
      </visual>
      <collision>
        <origin xyz="0 0 0" rpy="0 0 0"/>
        <geometry>
          <mesh filename="package://kuka_kr180_support/meshes/kr180_r3200_pa/collision/link_3.stl" />
        </geometry>
      </collision>
    </link>
    <link name="${prefix}link_4">
      <visual>
        <origin xyz="-0.35 0 -2.025" rpy="0 0 0"/>
        <geometry>
          <mesh filename="package://kuka_kr180_support/meshes/kr180_r3200_pa/visual/link_4.stl" />
        </geometry>
        <xacro:material_kuka_orange />
      </visual>
      <collision>
        <origin xyz="-0.35 0 -2.025" rpy="0 0 0"/>
        <geometry>
          <mesh filename="package://kuka_kr180_support/meshes/kr180_r3200_pa/collision/link_4.stl" />
        </geometry>
      </collision>
    </link>
    <link name="${prefix}link_5">
      <visual>
        <origin xyz="-1.57 0 -2.025" rpy="0 0 0"/>
        <geometry>
          <mesh filename="package://kuka_kr180_support/meshes/kr180_r3200_pa/visual/link_5.stl" />
        </geometry>
        <xacro:material_kuka_orange />
      </visual>
      <collision>
        <origin xyz="-1.57 0 -2.025" rpy="0 0 0"/>
        <geometry>
          <mesh filename="package://kuka_kr180_support/meshes/kr180_r3200_pa/collision/link_5.stl" />
        </geometry>
      </collision>
    </link>
    <link name="${prefix}link_6">
      <visual>
        <origin xyz="-1.85 0 1.775" rpy="${DEG2RAD * 180} 0 0"/>
        <geometry>
          <mesh filename="package://kuka_kr180_support/meshes/kr180_r3200_pa/visual/link_6.stl" />
        </geometry>
        <xacro:material_kuka_pedestal />
      </visual>
      <collision>
        <origin xyz="-1.85 0 1.775" rpy="${DEG2RAD * 180} 0 0"/>
        <geometry>
          <mesh filename="package://kuka_kr180_support/meshes/kr180_r3200_pa/collision/link_6.stl" />
        </geometry>
      </collision>
    </link>
    <!-- This frame corresponds to the $FLANGE coordinate system in KUKA KRC controllers. -->

    <joint name="${prefix}joint1" type="revolute">
      <origin xyz="0 0 0.675" rpy="0 0 0"/>
      <parent link="${prefix}base_link"/>
      <child link="${prefix}link_1"/>
      <axis xyz="0 0 -1"/>
      <limit effort="0" lower="${-DEG2RAD * 185}" upper="${DEG2RAD * 185}" velocity="${DEG2RAD * 105}"/>
    </joint>
    <joint name="${prefix}joint2" type="revolute">
      <origin xyz="0.350 0 0" rpy="0 ${DEG2RAD * 90} 0"/>
      <parent link="${prefix}link_1"/>
      <child link="${prefix}link_2"/>
      <axis xyz="0 1 0"/>
      <limit effort="0" lower="${-DEG2RAD * 140}" upper="${-DEG2RAD * 5}" velocity="${DEG2RAD * 107}"/>
    </joint>
    <joint name="${prefix}joint3" type="revolute">
      <origin xyz="0.0 0 1.35" rpy="0 -${DEG2RAD * 90} 0"/>
      <parent link="${prefix}link_2"/>
      <child link="${prefix}link_3"/>
      <axis xyz="0 1 0"/>
      <limit effort="0" lower="${-DEG2RAD * 0}" upper="${DEG2RAD * 0}" velocity="${DEG2RAD * 114}"/>
    </joint>
    <joint name="${prefix}joint4" type="revolute">
      <origin xyz="0 0 0" rpy="0 0 0"/>
      <parent link="${prefix}link_3"/>
      <child link="${prefix}link_4"/>
      <axis xyz="0 1 0"/>
      <limit effort="0" lower="${-DEG2RAD * 0}" upper="${DEG2RAD * 155}" velocity="${DEG2RAD * 114}"/>
    </joint>
    <joint name="${prefix}joint5" type="revolute">
      <origin xyz="1.22 0 0" rpy="0 0 0"/>
      <parent link="${prefix}link_4"/>
      <child link="${prefix}link_5"/>
      <axis xyz="0 1 0"/>
      <limit effort="0" lower="${-DEG2RAD * 130}" upper="${DEG2RAD * 60}" velocity="${DEG2RAD * 173}"/>
    </joint>
    <joint name="${prefix}joint6" type="revolute">
      <origin xyz="0.28 0 -0.25" rpy="0 ${DEG2RAD * 180} 0"/>
      <parent link="${prefix}link_5"/>
      <child link="${prefix}link_6"/>
      <axis xyz="0 0 -1"/>
      <limit effort="0" lower="${-DEG2RAD * 350}" upper="${DEG2RAD * 350}" velocity="${DEG2RAD * 242}"/>
    </joint>

  </xacro:macro>

  <transform>
    <xacro:attribute name="tf_rb_ub" value="0.0 0.0 0.0 0.0 0.0 0.0 1.0"/>
    <xacro:attribute name="tf_rf_uf" value="0.0 0.0 0.0 0.0 0.0 0.0 1.0"/>
  </transform>
  <constraint coeff="0.0 0.0 1.0 0.0 0.0 0.0" upper_bound="0.0" lower_bound="0.0"/>
  <constraint coeff="0.0 1.0 0.0 1.0 1.0 0.0" upper_bound="0.0" lower_bound="0.0"/>
  <joint_info dof="1 1 0 1 0 1"/>

</robot>
