<?xml version="1.0"?>
<robot xmlns:xacro="http://wiki.ros.org/xacro">
  <xacro:include filename="$(find fanuc_r2000ic_support)/urdf/common_materials.xacro"/>

  <xacro:macro name="fanuc_r2000ic_165f" params="prefix">
    <!-- links: main serial chain -->
    <link name="${prefix}base_link">
      <visual>
        <origin xyz="0 0 0" rpy="0 0 0"/>
        <geometry>
          <mesh filename="package://fanuc_r2000ic_support/meshes/r2000ic_165f/visual/base_link.stl"/>
        </geometry>
        <xacro:material_fanuc_gray40 />
      </visual>
      <collision>
        <origin xyz="0 0 0" rpy="0 0 0"/>
        <geometry>
          <mesh filename="package://fanuc_r2000ic_support/meshes/r2000ic_165f/collision/base_link.stl"/>
        </geometry>
      </collision>
    </link>
    <link name="${prefix}link_1">
      <visual>
        <origin xyz="0 0 0" rpy="0 0 0"/>
        <geometry>
          <mesh filename="package://fanuc_r2000ic_support/meshes/r2000ic_165f/visual/link_1.stl"/>
        </geometry>
        <xacro:material_fanuc_yellow />
      </visual>
      <collision>
        <origin xyz="0 0 0" rpy="0 0 0"/>
        <geometry>
          <mesh filename="package://fanuc_r2000ic_support/meshes/r2000ic_165f/collision/link_1.stl"/>
        </geometry>
      </collision>
    </link>
    <link name="${prefix}link_2">
      <visual>
        <origin xyz="0 0 0" rpy="0 0 0"/>
        <geometry>
          <mesh filename="package://fanuc_r2000ic_support/meshes/r2000ic_165f/visual/link_2.stl"/>
        </geometry>
        <xacro:material_fanuc_yellow />
      </visual>
      <collision>
        <origin xyz="0 0 0" rpy="0 0 0"/>
        <geometry>
          <mesh filename="package://fanuc_r2000ic_support/meshes/r2000ic_165f/collision/link_2.stl"/>
        </geometry>
      </collision>
    </link>
    <link name="${prefix}link_3">
      <visual>
        <origin xyz="0 0 0" rpy="0 0 0"/>
        <geometry>
          <mesh filename="package://fanuc_r2000ic_support/meshes/r2000ic_165f/visual/link_3.stl"/>
        </geometry>
        <xacro:material_fanuc_yellow />
      </visual>
      <collision>
        <origin xyz="0 0 0" rpy="0 0 0"/>
        <geometry>
          <mesh filename="package://fanuc_r2000ic_support/meshes/r2000ic_165f/collision/link_3.stl"/>
        </geometry>
      </collision>
    </link>
    <link name="${prefix}link_4">
      <visual>
        <origin xyz="0 0 0" rpy="0 0 0"/>
        <geometry>
          <mesh filename="package://fanuc_r2000ic_support/meshes/r2000ic_165f/visual/link_4.stl"/>
        </geometry>
        <xacro:material_fanuc_yellow />
      </visual>
      <collision>
        <origin xyz="0 0 0" rpy="0 0 0"/>
        <geometry>
          <mesh filename="package://fanuc_r2000ic_support/meshes/r2000ic_165f/collision/link_4.stl"/>
        </geometry>
      </collision>
    </link>
    <link name="${prefix}link_5">
      <visual>
        <origin xyz="0 0 0" rpy="0 0 0"/>
        <geometry>
          <mesh filename="package://fanuc_r2000ic_support/meshes/r2000ic_165f/visual/link_5.stl"/>
        </geometry>
        <xacro:material_fanuc_yellow />
      </visual>
      <collision>
        <origin xyz="0 0 0" rpy="0 0 0"/>
        <geometry>
          <mesh filename="package://fanuc_r2000ic_support/meshes/r2000ic_165f/collision/link_5.stl"/>
        </geometry>
      </collision>
    </link>
    <link name="${prefix}link_6">
      <visual>
        <origin xyz="0 0 0" rpy="0 ${radians(90)} 0"/>
        <geometry>
          <mesh filename="package://fanuc_r2000ic_support/meshes/r2000ic_165f/visual/link_6.stl"/>
        </geometry>
        <xacro:material_fanuc_black />
      </visual>
      <collision>
        <origin xyz="0 0 0" rpy="0 ${radians(90)} 0"/>
        <geometry>
          <mesh filename="package://fanuc_r2000ic_support/meshes/r2000ic_165f/collision/link_6.stl"/>
        </geometry>
      </collision>
    </link>

    <!-- joints: main serial chain -->
    <joint name="${prefix}joint1" type="revolute">
      <origin xyz="0 0 0.670" rpy="0 0 0"/>
      <parent link="${prefix}base_link"/>
      <child link="${prefix}link_1"/>
      <axis xyz="0 0 1"/>
      <limit lower="${radians(-185)}" upper="${radians(185)}" effort="0" velocity="${radians(120)}"/>
    </joint>
    <joint name="${prefix}joint2" type="revolute">
      <origin xyz="0.312 0 0" rpy="0 0 0"/>
      <parent link="${prefix}link_1"/>
      <child link="${prefix}link_2"/>
      <axis xyz="0 1 0"/>
      <limit lower="${radians(-60)}" upper="${radians(76)}" effort="0" velocity="${radians(105)}"/>
    </joint>
    <joint name="${prefix}joint3" type="revolute">
      <origin xyz="0 0 1.075" rpy="0 0 0"/>
      <parent link="${prefix}link_2"/>
      <child link="${prefix}link_3"/>
      <axis xyz="0 -1 0"/>
      <limit lower="${radians(-78)}" upper="${radians(179)}" effort="0" velocity="${radians(110)}"/>
    </joint>
    <joint name="${prefix}joint4" type="revolute">
      <origin xyz="0 0 0.225" rpy="0 0 0"/>
      <parent link="${prefix}link_3"/>
      <child link="${prefix}link_4"/>
      <axis xyz="-1 0 0"/>
      <limit lower="${radians(-360)}" upper="${radians(360)}" effort="0" velocity="${radians(140)}"/>
    </joint>
    <joint name="${prefix}joint5" type="revolute">
      <origin xyz="1.280 0 0" rpy="0 0 0"/>
      <parent link="${prefix}link_4"/>
      <child link="${prefix}link_5"/>
      <axis xyz="0 -1 0"/>
      <limit lower="${radians(-125)}" upper="${radians(125)}" effort="0" velocity="${radians(140)}"/>
    </joint>
    <joint name="${prefix}joint6" type="revolute">
      <origin xyz="0.215 0 0" rpy="3.1415926 -1.570796 0"/>
      <parent link="${prefix}link_5"/>
      <child link="${prefix}link_6"/>
      <axis xyz="0 0 -1"/>
      <limit lower="${radians(-360)}" upper="${radians(360)}" effort="0" velocity="${radians(220)}"/>
    </joint>
  </xacro:macro>

  <transform>
    <xacro:attribute name="tf_rb_ub" value="0.0 0.0 -0.67 0.0 0.0 0.0 1.0"/>
    <xacro:attribute name="tf_rf_uf" value="0.0 0.0 0.0 0.0 0.0 1.0 0.0"/>
  </transform>
  <constraint coeff="0.0 0.0 0.0 1.0 0.0 0.0" lower_bound="0.0" upper_bound="0.0"/>
  <constraint coeff="0.0 1.0 -1.0 0.0 -1.0 0.0" lower_bound="1.5707963267948966" upper_bound="1.5707963267948966"/>

</robot>
